Workbook

Sheet life
D1: object | E1: result | F1: 2021-2025 | H1: 2026-2030 | J1: 2031-2035 | L1: 2036-2040
A2: 人生目标 | B2: 个人 | C2: 身体
C3: 精神
C4: 智力
C5: 情感
B6: 伴侣
B7: 儿子
B8: 兄长
B9: 父亲
B10: 朋友
B11: 雇员
B12: 同事
B13: 社会个体
B14: 企业家

Sheet 4 个 5 年
D1: object | E1: result | F1: 第1年 | H1: 第2年 | J1: 第3年 | L1: 第4年 | N1: 第5年
A2: 2021-2025 | B2: 个人 | C2: 身体 | D2: ='life'!F2&""
C3: 精神 | D3: =life!F3&""
C4: 智力 | D4: =life!F4&""
C5: 情感 | D5: =life!F5&""
B6: 伴侣 | D6: =life!F6&""
B7: 儿子 | D7: =life!F7&""
B8: 兄长 | D8: =life!F8&""
B9: 父亲 | D9: =life!F9&""
B10: 朋友 | D10: ='life'!F10&""
B11: 雇员 | D11: =life!F11&""
B12: 同事 | D12: =life!F12&""
B13: 社会个体 | D13: =life!F13&""
B14: 企业家 | D14: =life!F14&""
A16: 2026-2030 | B16: 个人 | C16: 身体
C17: 精神
C18: 智力
C19: 情感
B20: 伴侣
B21: 儿子
B22: 兄长
B23: 父亲
B24: 朋友
B25: 雇员
B26: 同事
B27: 社会个体
B28: 企业家
A30: 2031-2035 | B30: 个人 | C30: 身体
C31: 精神
C32: 智力
C33: 情感
B34: 伴侣
B35: 儿子
B36: 兄长
B37: 父亲
B38: 朋友
B39: 雇员
B40: 同事
B41: 社会个体
B42: 企业家
...

Sheet 2021-2025
D1: object | E1: result | F1: 1月 | H1: 2月 | J1: 3月 | L1: 4月 | N1: 5月 | P1: 6月 | R1: 7月 | T1: 8月 | V1: 9月 | X1: 10月 | Z1: 11月 | AB1: 12月
A2: 2021 | B2: 个人 | C2: 身体
C3: 精神 | D3: ='4 个 5 年'!F3&""
C4: 智力 | D4: ='4 个 5 年'!F4&""
C5: 情感 | D5: ='4 个 5 年'!F5&""
B6: 伴侣 | D6: ='4 个 5 年'!F6&""
B7: 儿子 | D7: ='4 个 5 年'!F7&""
B8: 兄长 | D8: ='4 个 5 年'!F8&""
B9: 父亲 | D9: ='4 个 5 年'!F9&""
B10: 朋友 | D10: ='4 个 5 年'!F10&""
B11: 雇员 | D11: ='4 个 5 年'!F11&""
B12: 同事 | D12: ='4 个 5 年'!F12&""
B13: 社会个体 | D13: ='4 个 5 年'!F13&""
B14: 企业家 | D14: ='4 个 5 年'!F14&""
A16: 2022 | B16: 个人 | C16: 身体
C17: 精神
C18: 智力
C19: 情感
B20: 伴侣
B21: 儿子
B22: 兄长
B23: 父亲
B24: 朋友
B25: 雇员
B26: 同事
B27: 社会个体
B28: 企业家
A30: 2023 | B30: 个人 | C30: 身体
C31: 精神
C32: 智力
C33: 情感
B34: 伴侣
B35: 儿子
B36: 兄长
B37: 父亲
B38: 朋友
B39: 雇员
B40: 同事
B41: 社会个体
B42: 企业家
...

Sheet 2021Y
D1: object | E1: result | F1: 第1周 | H1: 第2周 | J1: 第3周 | L1: 第4周 | N1: 第5周
A2: 1 | B2: 个人 | C2: 身体
C3: 精神
C4: 智力
C5: 情感
B6: 伴侣
B7: 儿子
B8: 兄长
B9: 父亲
B10: 朋友
B11: 雇员
B12: 同事
B13: 社会个体
B14: 企业家
A16: 2 | B16: 个人 | C16: 身体
C17: 精神
C18: 智力
C19: 情感
B20: 伴侣
B21: 儿子
B22: 兄长
B23: 父亲
B24: 朋友
B25: 雇员
B26: 同事
B27: 社会个体
B28: 企业家
A30: 3 | B30: 个人 | C30: 身体
C31: 精神
C32: 智力
C33: 情感
B34: 伴侣
B35: 儿子
B36: 兄长
B37: 父亲
B38: 朋友
B39: 雇员
B40: 同事
B41: 社会个体
B42: 企业家
...

Sheet 2021Y5M
D1: object | E1: result | F1: 周一 | H1: 周二 | J1: 周三 | L1: 周四 | N1: 周五 | P1: 周六 | R1: 周日
A2: 5.3 - 5.9 | B2: 个人 | C2: 身体
C3: 精神
C4: 智力
C5: 情感
B6: 伴侣
B7: 儿子
B8: 兄长
B9: 父亲
B10: 朋友
B11: 雇员
B12: 同事
B13: 社会个体
B14: 企业家
A16: 5.10 - 5.16 | B16: 个人 | C16: 身体
C17: 精神
C18: 智力
C19: 情感
B20: 伴侣
B21: 儿子
B22: 兄长
B23: 父亲
B24: 朋友
B25: 雇员
B26: 同事
B27: 社会个体
B28: 企业家
A30: 5.17 - 5.23 | B30: 个人 | C30: 身体
C31: 精神
C32: 智力
C33: 情感
B34: 伴侣
B35: 儿子
B36: 兄长
B37: 父亲
B38: 朋友
B39: 雇员
B40: 同事
B41: 社会个体
B42: 企业家
...

Sheet 2021Y5M4W
D1: object | E1: result | F1: 09:00 - 09:30 | G1: 09:30 - 10:00 | H1: 10:00 - 10:30 | I1: 10:30 - 11:00 | J1: 11:00 - 11:30 | K1: 11:30 - 12:00 | L1: 12:00 - 12:30 | M1: 12:30 - 13:00 | N1: 13:00 - 13:30 | O1: 13:30 - 14:00 | P1: 14:00 - 14:30 | Q1: 14:30 - 15:00 | R1: 15:00 - 15:30 | S1: 15:30 - 16:00 | T1: 16:00 - 16:30 | U1: 16:30 - 17:00 | V1: 17:00 - 17:30 | W1: 17:30 - 18:00 | X1: 18:00 - 18:30 | Y1: 18:30 - 19:00 | Z1: 19:00 - 19:30 | AA1: 19:30 - 20:00 | AB1: 20:00 - 20:30 | AC1: 20:30 - 21:00 | AD1: 21:00 - 21:30 | AE1: 21:30 - 22:00 | AF1: 22:00 - 22:30 | AG1: 22:30 - 23:00
A2: 44340 | B2: 个人 | C2: 身体
C3: 精神
C4: 智力
C5: 情感
B6: 伴侣
B7: 儿子
B8: 兄长
B9: 父亲
B10: 朋友
B11: 雇员
B12: 同事
B13: 社会个体
B14: 企业家
A16: 44341 | B16: 个人 | C16: 身体
C17: 精神
C18: 智力
C19: 情感
B20: 伴侣
B21: 儿子
B22: 兄长
B23: 父亲
B24: 朋友
B25: 雇员
B26: 同事
B27: 社会个体
B28: 企业家
A30: 44342 | B30: 个人 | C30: 身体
C31: 精神
C32: 智力
C33: 情感
B34: 伴侣
B35: 儿子
B36: 兄长
B37: 父亲
B38: 朋友
B39: 雇员
B40: 同事
B41: 社会个体
B42: 企业家
...
